<?xml version="1.0" ?>
<robot name="manipulator_wheel" xmlns:xacro="http://www.ros.org/wiki/xacro">

<xacro:include filename="$(find manipulator_wheel_description)/urdf/materials.xacro" />
<xacro:include filename="$(find manipulator_wheel_description)/urdf/manipulator_wheel.trans" />
<xacro:include filename="$(find manipulator_wheel_description)/urdf/manipulator_wheel.gazebo" />
<link name="base_link">
  <inertial>
    <origin xyz="-0.022926233564164476 -0.15167370000685323 -0.05296974004025843" rpy="0 0 0"/>
    <mass value="76.1154222860437"/>
    <inertia ixx="1.295628" iyy="1.21986" izz="1.794207" ixy="-0.001778" iyz="-0.144288" ixz="-0.000193"/>
  </inertial>
  <visual>
    <origin xyz="0 0 0" rpy="0 0 0"/>
    <geometry>
      <mesh filename="package://manipulator_wheel_description/meshes/base_link.stl" scale="0.001 0.001 0.001"/>
    </geometry>
    <material name="silver"/>
  </visual>
  <collision>
    <origin xyz="0 0 0" rpy="0 0 0"/>
    <geometry>
      <mesh filename="package://manipulator_wheel_description/meshes/base_link.stl" scale="0.001 0.001 0.001"/>
    </geometry>
  </collision>
</link>

<link name="link_1_1">
  <inertial>
    <origin xyz="-0.0665838793626529 0.00018951907097419785 -0.15592397147705364" rpy="0 0 0"/>
    <mass value="13.56198472678475"/>
    <inertia ixx="0.174021" iyy="0.201032" izz="0.052132" ixy="1e-06" iyz="0.000182" ixz="-0.000954"/>
  </inertial>
  <visual>
    <origin xyz="-0.043929 0.27 0.075161" rpy="0 0 0"/>
    <geometry>
      <mesh filename="package://manipulator_wheel_description/meshes/link_1_1.stl" scale="0.001 0.001 0.001"/>
    </geometry>
    <material name="silver"/>
  </visual>
  <collision>
    <origin xyz="-0.043929 0.27 0.075161" rpy="0 0 0"/>
    <geometry>
      <mesh filename="package://manipulator_wheel_description/meshes/link_1_1.stl" scale="0.001 0.001 0.001"/>
    </geometry>
  </collision>
</link>

<link name="link_2_1">
  <inertial>
    <origin xyz="-0.06809929368163971 0.011545009334163414 0.028880101791727508" rpy="0 0 0"/>
    <mass value="14.98901864726029"/>
    <inertia ixx="0.147432" iyy="0.060352" izz="0.106188" ixy="0.000519" iyz="0.039686" ixz="-6.3e-05"/>
  </inertial>
  <visual>
    <origin xyz="-0.043929 0.269597 0.405161" rpy="0 0 0"/>
    <geometry>
      <mesh filename="package://manipulator_wheel_description/meshes/link_2_1.stl" scale="0.001 0.001 0.001"/>
    </geometry>
    <material name="silver"/>
  </visual>
  <collision>
    <origin xyz="-0.043929 0.269597 0.405161" rpy="0 0 0"/>
    <geometry>
      <mesh filename="package://manipulator_wheel_description/meshes/link_2_1.stl" scale="0.001 0.001 0.001"/>
    </geometry>
  </collision>
</link>

<link name="link_3_1">
  <inertial>
    <origin xyz="1.0447027681572546e-05 -0.09869607635588817 -0.033099829009288595" rpy="0 0 0"/>
    <mass value="8.318553158253737"/>
    <inertia ixx="0.041743" iyy="0.008031" izz="0.043189" ixy="-4e-06" iyz="0.000761" ixz="-4e-06"/>
  </inertial>
  <visual>
    <origin xyz="0.024071 0.349597 0.374661" rpy="0 0 0"/>
    <geometry>
      <mesh filename="package://manipulator_wheel_description/meshes/link_3_1.stl" scale="0.001 0.001 0.001"/>
    </geometry>
    <material name="silver"/>
  </visual>
  <collision>
    <origin xyz="0.024071 0.349597 0.374661" rpy="0 0 0"/>
    <geometry>
      <mesh filename="package://manipulator_wheel_description/meshes/link_3_1.stl" scale="0.001 0.001 0.001"/>
    </geometry>
  </collision>
</link>

<link name="link_4_1">
  <inertial>
    <origin xyz="-0.027200014024595785 -0.04184068486015846 0.022474329238523383" rpy="0 0 0"/>
    <mass value="6.3799372618247645"/>
    <inertia ixx="0.016749" iyy="0.026699" izz="0.027086" ixy="-0.000559" iyz="-0.003876" ixz="0.002353"/>
  </inertial>
  <visual>
    <origin xyz="0.024077 0.563097 0.404661" rpy="0 0 0"/>
    <geometry>
      <mesh filename="package://manipulator_wheel_description/meshes/link_4_1.stl" scale="0.001 0.001 0.001"/>
    </geometry>
    <material name="silver"/>
  </visual>
  <collision>
    <origin xyz="0.024077 0.563097 0.404661" rpy="0 0 0"/>
    <geometry>
      <mesh filename="package://manipulator_wheel_description/meshes/link_4_1.stl" scale="0.001 0.001 0.001"/>
    </geometry>
  </collision>
</link>

<link name="link_5_1">
  <inertial>
    <origin xyz="0.04870811402579993 0.07158062518210029 -0.10422729249502255" rpy="0 0 0"/>
    <mass value="16.57525103442224"/>
    <inertia ixx="0.14344" iyy="0.0654" izz="0.102348" ixy="-0.000885" iyz="0.029739" ixz="0.000823"/>
  </inertial>
  <visual>
    <origin xyz="0.072079 0.649596 0.404661" rpy="0 0 0"/>
    <geometry>
      <mesh filename="package://manipulator_wheel_description/meshes/link_5_1.stl" scale="0.001 0.001 0.001"/>
    </geometry>
    <material name="silver"/>
  </visual>
  <collision>
    <origin xyz="0.072079 0.649596 0.404661" rpy="0 0 0"/>
    <geometry>
      <mesh filename="package://manipulator_wheel_description/meshes/link_5_1.stl" scale="0.001 0.001 0.001"/>
    </geometry>
  </collision>
</link>

<link name="tcp_1">
  <inertial>
    <origin xyz="-4.204320017894836e-07 -1.4896289834975818e-07 0.0005999834596194242" rpy="0 0 0"/>
    <mass value="0.10295683993012651"/>
    <inertia ixx="9.6e-05" iyy="9.6e-05" izz="0.000192" ixy="-0.0" iyz="0.0" ixz="0.0"/>
  </inertial>
  <visual>
    <origin xyz="0.021738 0.649258 0.604661" rpy="0 0 0"/>
    <geometry>
      <mesh filename="package://manipulator_wheel_description/meshes/tcp_1.stl" scale="0.001 0.001 0.001"/>
    </geometry>
    <material name="silver"/>
  </visual>
  <collision>
    <origin xyz="0.021738 0.649258 0.604661" rpy="0 0 0"/>
    <geometry>
      <mesh filename="package://manipulator_wheel_description/meshes/tcp_1.stl" scale="0.001 0.001 0.001"/>
    </geometry>
  </collision>
</link>

<joint name="Rev1" type="continuous">
  <origin xyz="0.043929 -0.27 -0.075161" rpy="0 0 0"/>
  <parent link="base_link"/>
  <child link="link_1_1"/>
  <axis xyz="-1.0 0.0 0.0"/>
</joint>

<joint name="Rev6" type="continuous">
  <origin xyz="0.0 0.000403 -0.33" rpy="0 0 0"/>
  <parent link="link_1_1"/>
  <child link="link_2_1"/>
  <axis xyz="1.0 -0.0 -0.0"/>
</joint>

<joint name="Rev8" type="continuous">
  <origin xyz="-0.068 -0.08 0.0305" rpy="0 0 0"/>
  <parent link="link_2_1"/>
  <child link="link_3_1"/>
  <axis xyz="-0.0 -0.0 -1.0"/>
</joint>

<joint name="Rev9" type="continuous">
  <origin xyz="-6e-06 -0.2135 -0.03" rpy="0 0 0"/>
  <parent link="link_3_1"/>
  <child link="link_4_1"/>
  <axis xyz="-2.9e-05 -1.0 0.0"/>
</joint>

<joint name="Rev14" type="continuous">
  <origin xyz="-0.048002 -0.086499 0.0" rpy="0 0 0"/>
  <parent link="link_4_1"/>
  <child link="link_5_1"/>
  <axis xyz="1.0 -2.9e-05 0.0"/>
</joint>

<joint name="Rev15" type="continuous">
  <origin xyz="0.050341 0.000338 -0.2" rpy="0 0 0"/>
  <parent link="link_5_1"/>
  <child link="tcp_1"/>
  <axis xyz="-0.0 -0.0 -1.0"/>
</joint>

</robot>
